Workbook

Sheet Stamps
A1: ID | B1: Chapter | C1: Stamp name | D1: What earns it | E1: Kind | F1: Tier 1 (Select) | G1: Tier 2 (Choice) | H1: Tier 3 (Prime) | I1: Tier 4 (A5 Wagyu) | J1: Hidden? | K1: Backfill from stats | L1: Keep? | M1: Your notes
A2: house_open | B2: House | C2: Open for Business | D2: Your first cutscene | E2: Single | J2: No | K2: Yes | L2: Yes
A3: house_regular | B3: House | C3: Regular | D3: Real cutscenes watched | E3: Tiered | F3: 100 | G3: 1000 | H3: 5000 | I3: 10000 | J3: No | K3: Yes | L3: Yes
A4: house_full_menu | B4: House | C4: Full Menu | D4: At least one kill in every chapter | E4: Single | J4: No | K4: Yes | L4: Yes
A5: house_always_wins | B5: House | C5: The House Always Wins | D5: Busts in a row, all animations together | E5: Single | F5: 50 | J5: No | K5: No | L5: Yes
A6: house_hot_streak | B6: House | C6: Hot Streak | D6: Two rare drops within 10 minutes | E6: Single | J6: No | K6: No | L6: Yes
A7: house_tycoon | B7: House | C7: Tycoon | D7: Coins of drops revealed (lifetime) | E7: Tiered | F7: 10000000 | G7: 100000000 | H7: 1000000000 | I7: 10000000000 | J7: No | K7: No | L7: Yes
A8: house_places_to_be | B8: House | C8: I Have Places to Be | D8: Cutscenes skipped | E8: Single | F8: 100 | J8: No | K8: No | L8: Yes
A9: house_night_shift | B9: House | C9: Night Shift | D9: A rare drop between 3 and 5 AM | E9: Single | J9: Yes | K9: No | L9: Yes
A10: house_jackpot_777 | B10: House | C10: Jackpot 777 | D10: A rare drop on exactly your 777th kill of anything | E10: Single | J10: Yes | K10: No | L10: Yes
A11: scatha_worm_food | B11: Scatha | C11: Worm Food | D11: Scatha kills | E11: Tiered | F11: 50 | G11: 100 | H11: 500 | I11: 1000 | J11: No | K11: Yes | L11: Yes
A12: scatha_rare_cut | B12: Scatha | C12: Rare Cut | D12: A rare Scatha pet | E12: Single | J12: No | K12: Yes | L12: Yes
A13: scatha_choice_cut | B13: Scatha | C13: Choice Cut | D13: An epic Scatha pet | E13: Single | J13: No | K13: Yes | L13: Yes
A14: scatha_prime_cut | B14: Scatha | C14: Prime Cut | D14: A legendary Scatha pet | E14: Single | J14: No | K14: Yes | L14: Yes
A15: scatha_full_set | B15: Scatha | C15: Full Set | D15: All three pet rarities | E15: Single | J15: No | K15: Yes | L15: Yes
A16: scatha_beginners_luck | B16: Scatha | C16: Beginner's Luck | D16: A pet within your first N kills | E16: Single | F16: 20 | J16: No | K16: Partly | L16: Yes
A17: scatha_dry_aged | B17: Scatha | C17: Dry Aged | D17: Kills in a row without a pet | E17: Single | F17: 100 | J17: No | K17: Yes | L17: Yes
A18: scatha_dry_aged_45 | B18: Scatha | C18: Dry Aged 45 Days | D18: Kills in a row without a pet | E18: Single | F18: 200 | J18: Yes | K18: Yes | L18: Yes
A19: scatha_slippery | B19: Scatha | C19: Slippery | D19: Times the Scatha ducks your last swing | E19: Single | F19: 50 | J19: No | K19: Yes | L19: Yes
A20: scatha_back_to_back | B20: Scatha | C20: Back to Back | D20: Two pets within N kills | E20: Single | F20: 50 | J20: No | K20: No | L20: Yes
A21: scatha_dozen | B21: Scatha | C21: A Butcher's Dozen | D21: Pets in total | E21: Single | F21: 13 | J21: No | K21: Yes | L21: Yes
A22: vg_thawed_out | B22: Vanguard | C22: Thawed Out | D22: Vanguard corpses opened | E22: Tiered | F22: 5 | G22: 25 | H22: 50 | I22: 100 | J22: No | K22: Yes | L22: Yes
A23: vg_cold_hands | B23: Vanguard | C23: Cold Hands | D23: A legendary drop | E23: Single | J23: No | K23: Yes | L23: Yes
A24: vg_heart_of_glass | B24: Vanguard | C24: Heart of Glass | D24: The Shattered Locket | E24: Single | J24: No | K24: Yes | L24: Yes
A25: vg_frostbitten | B25: Vanguard | C25: Frostbitten | D25: The Frostbitten Dye | E25: Single | J25: No | K25: Yes | L25: Yes
A26: vg_ice_cold | B26: Vanguard | C26: Ice Cold | D26: Corpses in a row without a legendary | E26: Single | F26: 25 | J26: No | K26: Yes | L26: Yes | M26: Claude: was 'nothing above common'. Your stats count corpses since a legendary, so this way it can be backfilled.
A27: vg_negative_equity | B27: Vanguard | C27: Negative Equity | D27: A corpse worth less than its Skeleton Key | E27: Single | J27: No | K27: No | L27: Yes
A28: vg_in_the_black | B28: Vanguard | C28: In the Black | D28: A corpse worth at least N coins | E28: Single | F28: 30000000 | J28: No | K28: No | L28: Yes
A29: diana_heads | B29: Diana | C29: Off With Their Heads | D29: Diana creature kills | E29: Tiered | F29: 50 | G29: 250 | H29: 1000 | I29: 5000 | J29: No | K29: Yes | L29: Yes
A30: diana_brain_food | B30: Diana | C30: Food for Thought | D30: Brain Food | E30: Single | J30: No | K30: Yes | L30: Yes
A31: diana_chimera | B31: Diana | C31: Glint in the Eye | D31: Chimera I | E31: Single | J31: No | K31: Yes | L31: Yes
A32: diana_stinger | B32: Diana | C32: Sting Operation | D32: Fateful Stinger | E32: Single | J32: No | K32: Yes | L32: Yes
A33: diana_manticore | B33: Diana | C33: Heart of the Beast | D33: Manti-core | E33: Single | J33: No | K33: Yes | L33: Yes
A34: diana_crown | B34: Diana | C34: Greed is Good | D34: Crown of Greed | E34: Single | J34: No | K34: Yes | L34: Yes
A35: diana_wool | B35: Diana | C35: Golden Fleece | D35: Shimmering Wool | E35: Single | J35: No | K35: Yes | L35: Yes
A36: diana_relic | B36: Diana | C36: Relic Hunter | D36: Minos Relic | E36: Single | J36: No | K36: Yes | L36: Yes
A37: diana_dye | B37: Diana | C37: The Whole Hunt | D37: Mythological Dye | E37: Single | J37: No | K37: Yes | L37: Yes
A38: diana_pantheon | B38: Diana | C38: Pantheon | D38: All eight Diana drops | E38: Single | J38: No | K38: Yes | L38: Yes
A39: diana_shared_custody | B39: Diana | C39: Shared Custody | D39: A win from loot share | E39: Single | J39: Yes | K39: No | L39: Yes
A40: hellion_fire_watch | B40: Hellion | C40: Fire Watch | D40: Tier IV Demonlords killed | E40: Tiered | F40: 25 | G40: 100 | H40: 500 | I40: 1000 | J40: No | K40: Yes | L40: Yes
...

Sheet How to edit
A1: The Butcher's Ledger - stamp list
A3: Edit the yellow cells. Everything else is filled in for you or worked out from your edits.
A5: Stamps sheet - one row per stamp:
A6: Keep? Yes / No. Set No to cut a stamp without deleting its row.
A7: Stamp name Rename freely.
A8: What earns it The rule in plain words.
A9: Kind Single (one stamp) or Tiered (a ladder of grades).
A10: Tier columns The number needed for each grade. A Single stamp with a number uses only the first column.
A11: Hidden? Yes = shows as ??? in the book until earned.
A12: Your notes Anything for me: jokes, changes, questions.
A14: Do not change the ID column: it is how I match your edits to the code. New stamps get a new ID.
A15: To add a stamp, fill in a new row at the bottom, for example:
... A20: Chapters sheet: counts per chapter, worked out from the Stamps sheet.

Sheet Chapters
A1: Chapter | B1: What it covers | C1: Colour | D1: Stamps kept | E1: Hidden kept | F1: Tiered kept | G1: Cut
A2: House | B2: Across all animations | C2: Gold #E8B04A | D2: =COUNTIFS(Stamps!$B:$B,$A2,Stamps!$L:$L,"Yes") | E2: =COUNTIFS(Stamps!$B:$B,$A2,Stamps!$L:$L,"Yes",Stamps!$J:$J,"Yes") | F2: =COUNTIFS(Stamps!$B:$B,$A2,Stamps!$L:$L,"Yes",Stamps!$E:$E,"Tiered") | G2: =COUNTIFS(Stamps!$B:$B,$A2,Stamps!$L:$L,"No")
A3: Scatha | B3: The Cleaver | C3: Purple | D3: =COUNTIFS(Stamps!$B:$B,$A3,Stamps!$L:$L,"Yes") | E3: =COUNTIFS(Stamps!$B:$B,$A3,Stamps!$L:$L,"Yes",Stamps!$J:$J,"Yes") | F3: =COUNTIFS(Stamps!$B:$B,$A3,Stamps!$L:$L,"Yes",Stamps!$E:$E,"Tiered") | G3: =COUNTIFS(Stamps!$B:$B,$A3,Stamps!$L:$L,"No")
A4: Vanguard | B4: The Thaw | C4: Ice blue | D4: =COUNTIFS(Stamps!$B:$B,$A4,Stamps!$L:$L,"Yes") | E4: =COUNTIFS(Stamps!$B:$B,$A4,Stamps!$L:$L,"Yes",Stamps!$J:$J,"Yes") | F4: =COUNTIFS(Stamps!$B:$B,$A4,Stamps!$L:$L,"Yes",Stamps!$E:$E,"Tiered") | G4: =COUNTIFS(Stamps!$B:$B,$A4,Stamps!$L:$L,"No")
A5: Diana | B5: The Chopping Block | C5: Red | D5: =COUNTIFS(Stamps!$B:$B,$A5,Stamps!$L:$L,"Yes") | E5: =COUNTIFS(Stamps!$B:$B,$A5,Stamps!$L:$L,"Yes",Stamps!$J:$J,"Yes") | F5: =COUNTIFS(Stamps!$B:$B,$A5,Stamps!$L:$L,"Yes",Stamps!$E:$E,"Tiered") | G5: =COUNTIFS(Stamps!$B:$B,$A5,Stamps!$L:$L,"No")
A6: Hellion | B6: Inferno Demonlord IV | C6: Orange | D6: =COUNTIFS(Stamps!$B:$B,$A6,Stamps!$L:$L,"Yes") | E6: =COUNTIFS(Stamps!$B:$B,$A6,Stamps!$L:$L,"Yes",Stamps!$J:$J,"Yes") | F6: =COUNTIFS(Stamps!$B:$B,$A6,Stamps!$L:$L,"Yes",Stamps!$E:$E,"Tiered") | G6: =COUNTIFS(Stamps!$B:$B,$A6,Stamps!$L:$L,"No")
A7: Eruption | B7: Lava fishing | C7: Lava orange | D7: =COUNTIFS(Stamps!$B:$B,$A7,Stamps!$L:$L,"Yes") | E7: =COUNTIFS(Stamps!$B:$B,$A7,Stamps!$L:$L,"Yes",Stamps!$J:$J,"Yes") | F7: =COUNTIFS(Stamps!$B:$B,$A7,Stamps!$L:$L,"Yes",Stamps!$E:$E,"Tiered") | G7: =COUNTIFS(Stamps!$B:$B,$A7,Stamps!$L:$L,"No")
A8: Fin | B8: Fishing Festival | C8: Sea blue | D8: =COUNTIFS(Stamps!$B:$B,$A8,Stamps!$L:$L,"Yes") | E8: =COUNTIFS(Stamps!$B:$B,$A8,Stamps!$L:$L,"Yes",Stamps!$J:$J,"Yes") | F8: =COUNTIFS(Stamps!$B:$B,$A8,Stamps!$L:$L,"Yes",Stamps!$E:$E,"Tiered") | G8: =COUNTIFS(Stamps!$B:$B,$A8,Stamps!$L:$L,"No")
A9: Wisp | B9: Dwarven Mines Ghosts | C9: Pale cyan | D9: =COUNTIFS(Stamps!$B:$B,$A9,Stamps!$L:$L,"Yes") | E9: =COUNTIFS(Stamps!$B:$B,$A9,Stamps!$L:$L,"Yes",Stamps!$J:$J,"Yes") | F9: =COUNTIFS(Stamps!$B:$B,$A9,Stamps!$L:$L,"Yes",Stamps!$E:$E,"Tiered") | G9: =COUNTIFS(Stamps!$B:$B,$A9,Stamps!$L:$L,"No")
A10: Seraph | B10: Voidgloom Seraph IV (taped - under maintenance) | C10: Violet | D10: =COUNTIFS(Stamps!$B:$B,$A10,Stamps!$L:$L,"Yes") | E10: =COUNTIFS(Stamps!$B:$B,$A10,Stamps!$L:$L,"Yes",Stamps!$J:$J,"Yes") | F10: =COUNTIFS(Stamps!$B:$B,$A10,Stamps!$L:$L,"Yes",Stamps!$E:$E,"Tiered") | G10: =COUNTIFS(Stamps!$B:$B,$A10,Stamps!$L:$L,"No")
A11: Total | D11: =SUM(D2:D10) | E11: =SUM(E2:E10) | F11: =SUM(F2:F10) | G11: =SUM(G2:G10)

Sheet Decisions
A1: Question | B1: My suggestion | C1: Your answer
A2: Name of the book (the new tab) | B2: The Butcher's Ledger
A3: Tier names, lowest to highest | B3: Select, Choice, Prime, A5 Wagyu (grades of beef)
A4: Stamp pop-up in game when you earn one | B4: On by default, can be switched off
A5: Stamps earned before the update | B5: Stamped as PRE-LEDGER, no date
A6: Seraph chapter while under maintenance | B6: Taped page, no stamps listed
A7: Shareable stamp image (save a PNG of a stamp) | B7: Later, not in the first version
